#VRML_SIM R2019a utf8
DEF _world WorldInfo {
}
DEF _camera Viewpoint {
  orientation 1 0 0 5.682064919251758
  position 0 4.643008770262436 6.479439839471
}
DEF my_robot Robot {
  translation 0 0 1.5
  rotation -5.8642908336531095e-08 0.9999999999999983 8.076646741804479e-14 3.141592643999999
  children [
    DEF FL Transform {
      translation -0.125 -0.049999999999999996 -0.1
      children [
        HingeJoint {
          jointParameters HingeJointParameters {
            position 7.957737318159665e-11
          }
          device [
            RotationalMotor {
              name "front_left"
              maxVelocity 20
            }
          ]
          endPoint Solid {
            rotation 3.2734138996434746e-09 -3.2734247842059866e-09 1 1.570799693899574
            children [
              DEF wheel Shape {
                appearance Appearance {
                  material Material {
                  }
                }
                geometry Cylinder {
                  height 0.049999999999999996
                  radius 0.05
                }
              }
            ]
            boundingObject USE wheel
            physics Physics {
            }
          }
        }
      ]
    }
    DEF FR Transform {
      translation 0.125 -0.049999999999999996 -0.1
      children [
        HingeJoint {
          jointParameters HingeJointParameters {
            position 6.524944264925872e-11
          }
          device [
            RotationalMotor {
              name "front_right"
              maxVelocity 20
            }
          ]
          endPoint Solid {
            rotation 2.6644786988098793e-09 -2.664487533020378e-09 1 1.570799693899574
            children [
              DEF wheel Shape {
                appearance Appearance {
                  material Material {
                  }
                }
                geometry Cylinder {
                  height 0.049999999999999996
                  radius 0.05
                }
              }
            ]
            name "solid(1)"
            boundingObject USE wheel
            physics Physics {
            }
          }
        }
      ]
    }
    DEF RL Transform {
      translation -0.125 -0.049999999999999996 0.1
      children [
        HingeJoint {
          jointParameters HingeJointParameters {
            position 6.525247906485026e-11
          }
          device [
            RotationalMotor {
              name "rear_left"
              maxVelocity 20
            }
          ]
          endPoint Solid {
            rotation 2.664609885553636e-09 -2.664618720205854e-09 1 1.570799693899574
            children [
              DEF wheel Shape {
                appearance Appearance {
                  material Material {
                  }
                }
                geometry Cylinder {
                  height 0.049999999999999996
                  radius 0.05
                }
              }
            ]
            name "solid(2)"
            boundingObject USE wheel
            physics Physics {
            }
          }
        }
      ]
    }
    DEF RR Transform {
      translation 0.125 -0.049999999999999996 0.1
      children [
        HingeJoint {
          jointParameters HingeJointParameters {
            position 7.957311537402311e-11
          }
          device [
            RotationalMotor {
              name "rear_right"
              maxVelocity 20
            }
          ]
          endPoint Solid {
            rotation 3.2732354286692036e-09 -3.2732463126307854e-09 1 1.570799693899574
            children [
              DEF wheel Shape {
                appearance Appearance {
                  material Material {
                  }
                }
                geometry Cylinder {
                  height 0.049999999999999996
                  radius 0.05
                }
              }
            ]
            name "solid(3)"
            boundingObject USE wheel
            physics Physics {
            }
          }
        }
      ]
    }
    DEF BODY Shape {
      appearance OldSteel {
        colorOverride 0.5 1 1
      }
      geometry Box {
        size 0.2 0.1 0.30000000000000004
      }
    }
  ]
  name "my_'robot"
  boundingObject USE BODY
  physics Physics {
  }
  controller "my_robot"
}
DEF _global_light DirectionalLight {
  ambientIntensity 1
  direction 0 -1 0
  intensity 0.7
  castShadows TRUE
}
DEF _lights Group {
  children [
    Solid {
      translation 0 1.550000000000001 -4
      children [
        PointLight {
          color 0.8 0.93 0.93
          location 0 0.3 0
        }
      ]
      name "solid(5)"
    }
    Solid {
      translation 1.7499999999999998 1.05 -3.3
      children [
        PointLight {
          color 1 0.8 0.8
          location 0 0.3 0
        }
      ]
      name "solid(4)"
    }
    Solid {
      translation -1.75 1.05 -3.3
      children [
        PointLight {
          color 1 0.8 0.8
          location 0 0.3 0
        }
      ]
      name "solid(3)"
    }
  ]
}
DEF _ground RectangleArena {
  translation 0 -0.12000000000000002 0
  floorSize 4 4
  floorTileSize 1 1
  floorAppearance ThreadMetalPlate {
  }
  wallThickness 0.015
  wallHeight 0.3
  wallAppearance OldSteel {
  }
}
DEF _coins Group {
  children [
    DEF COIN Transform {
      translation -1.5 0 -1.5
      rotation 0 1 0 28.383185307179726
      children [
        Transform {
          rotation 1 0 0 1.5707962836408271
          children [
            DEF Coin Shape {
              appearance Appearance {
                material Material {
                  diffuseColor 0.8730601968413825 0.8625162127107653 0
                }
              }
              geometry Cylinder {
                height 0.01
                radius 0.12
              }
            }
          ]
        }
      ]
    }
    DEF COIN Transform {
      translation 1.5 0 -1.5
      rotation 0 1 0 28.383185307179726
      children [
        Transform {
          rotation 1 0 0 1.5707962836408271
          children [
            DEF Coin Shape {
              appearance Appearance {
                material Material {
                  diffuseColor 0.8730601968413825 0.8625162127107653 0
                }
              }
              geometry Cylinder {
                height 0.01
                radius 0.12
              }
            }
          ]
        }
      ]
    }
    DEF COIN Transform {
      translation 0 0 -1
      rotation 0 1 0 28.383185307179726
      children [
        Transform {
          rotation 1 0 0 1.5707962836408271
          children [
            DEF Coin Shape {
              appearance Appearance {
                material Material {
                  diffuseColor 0.8730601968413825 0.8625162127107653 0
                }
              }
              geometry Cylinder {
                height 0.01
                radius 0.12
              }
            }
          ]
        }
      ]
    }
  ]
}
DEF _coin_handler Robot {
  name "_coin_handler"
  controller "_coin"
  supervisor TRUE
}
